Workbook

Sheet Sheet1
A1: Family | B1: What type of song is this? | C1: What region are you searching in? | D1: Enter the name of the culture this song was collected from. | E1: Glottocode_1 | F1: Glottocode_2 | G1: Glottocode_Final | H1: Family Glottocode | I1: Level | J1: Agree? | K1: Common Subfamily? | L1: Common Family? | M1: Notes | N1: ISOcode | O1: Classification Type | P1: Are you sure? | Q1: Enter the track name, as it appears in the source. | R1: Paste a hyperlink here that gets to the source material (e.g., the CD containing the track). | S1: List the track number of the song. | T1: What source(s) is this song listed in? | U1: Is there any secondary function for this song? | V1: Is this an unpublished track that came directly from an anthropologist? | W1: Name | X1: Affiliation | Y1: Email | Z1: Tell us about how you categorized this song. | AA1: Enter the label of the song here. | AB1: Information from ethnography | AC1: Information from lyrics | AD1: If necessary, provide additional information here about how to find this track. | AE1: Confirm here that you did not listen to the song until this point! | AF1: Is there at least one audible singer on the recording? | AG1: How easy is it to hear the singer(s)? | AH1: Do you have access to the audio of this song? | AI1: General notes | AJ1: Timestamp | AK1: What are your initials?
A2: =VLOOKUP(H2,Languages!$A$2:$B$430,2,FALSE) -> Abkhaz-Adyge | B2: Dance | C2: Caucasus | D2: Abkhazia | E2: abkh1244 | F2: abkh1244 | G2: abkh1244 | H2: =VLOOKUP(G2,'languoid 4.0'!$A$1:$I$24439,2,FALSE) -> abkh1242 | I2: =VLOOKUP(G2,'languoid 4.0'!$A$1:$I$24439,6,FALSE) -> language | J2: yes | K2: yes | L2: yes | N2: abk | O2: Exact Match | P2: I'm sure | Q2: Arkuashaga | R2: https://search.alexanderstreet.com/preview/work/bibliographic_entity%7Cliner_notes%7C2258560 | S2: Track 8 | T2: Garland Encyclopedia of World Music | U2: No secondary function | V2: No | Z2: There is text in associated ethnography that states what type of song this is (this could be in liner notes, it could be in an email from an anthropologist, etc) | AA2: NA | AB2: Dance song //ON ALEXANDER STREET, IN THE LINER NOTE OF THE ALBUM: The Golden Fleece - Caucasus, Vol. 2: Songs From Abkhazia & Adzharia, PAGE 10// | AC2: NA | AE2: I followed the instructions and I have not yet listened to it! | AF2: Yes | AG2: 6 | AH2: Yes | AJ2: 43259.649 | AK2: AZX
A3: =VLOOKUP(H3,Languages!$A$2:$B$430,2,FALSE) -> Abkhaz-Adyge | B3: Dance | C3: Caucasus | D3: Abkhazia | E3: abkh1244 | F3: abkh1244 | G3: abkh1244 | H3: =VLOOKUP(G3,'languoid 4.0'!$A$1:$I$24439,2,FALSE) -> abkh1242 | I3: =VLOOKUP(G3,'languoid 4.0'!$A$1:$I$24439,6,FALSE) -> language | J3: yes | K3: yes | L3: yes | N3: abk | O3: Exact Match | P3: I'm sure | Q3: Arkushaga | R3: https://search.alexanderstreet.com/preview/work/bibliographic_entity%7Cliner_notes%7C2258560 | S3: Track 23 | T3: Garland Encyclopedia of World Music | U3: No secondary function | V3: No | Z3: There is text in associated ethnography that states what type of song this is (this could be in liner notes, it could be in an email from an anthropologist, etc) | AA3: NA | AB3: Dance melody //ON ALEXANDER STREET, IN THE LINER NOTE OF THE ALBUM: The Golden Fleece - Caucasus, Vol. 2: Songs From Abkhazia & Adzharia, PAGE 11, DESCRIPTION OF SONG 23// | AC3: NA | AD3: Alexander St. lists voice as an instrument but no voice can be heard on recording | AE3: I followed the instructions and I have not yet listened to it! | AF3: No | AG3: 0 | AH3: Yes | AJ3: 43259.684 | AK3: AZX
A4: =VLOOKUP(H4,Languages!$A$2:$B$430,2,FALSE) -> Abkhaz-Adyge | B4: Dance | C4: Central Asia | D4: three different culture groups are represented in the choir who sings the song being Kamancha, chechen, tar | E4: kaba1278 | F4: . | G4: kaba1278 | H4: =VLOOKUP(G4,'languoid 4.0'!$A$1:$I$24439,2,FALSE) -> abkh1242 | I4: =VLOOKUP(G4,'languoid 4.0'!$A$1:$I$24439,6,FALSE) -> language | J4: no | K4: . | L4: . | N4: kbd | O4: Exact Match | P4: I'm sure | Q4: Lezghinka | R4: http://gofile.me/3T2hs/u9J7qpZTJ | S4: Track 2 | T4: Smithsonian Folkways, Before the Revolution | U4: No secondary function | V4: No | Z4: There is text in associated ethnography that states what type of song this is (this could be in liner notes, it could be in an email from an anthropologist, etc) | AA4: Lezghinka //HOLLIS NUMBER 990090350310203941 IN HARVARD ARCHIVE OF WORLD MUSIC HOLLIS RELEVANT TEXT IS IN THE LINEAR NOTES PG. 12// | AB4: Much of the music recorded can be divided into two types; male choirs (tracks 1,3 & 5), and instrumental dance music (tracks 2 &4). //HOLLIS NUMBER 990090350310203941 IN HARVARD ARCHIVE OF WORLD MUSIC HOLLIS RELEVANT TEXT IS IN THE LINEAR NOTES PG. 4// | AC4: NA | AD4: File Path on Synology: /NHS2/submissions/Central Asia/Before the revolution/2 Audio Track.aiff, https://d16klsh1z1xre7-cloudfront-net.ezp-prod1.hul.harvard.edu/dorp/liner/0/cc14/787d/1000089961-liner.pdf | AE4: I followed the instructions and I have not yet listened to it! | AF4: No | AG4: 1 | AH4: Yes | AJ4: 8/19/2018 18:34:37 | AK4: BSG
A5: =VLOOKUP(H5,Languages!$A$2:$B$430,2,FALSE) -> Abkhaz-Adyge | B5: Dance | C5: Central Asia | D5: Kabardian not found of eHARF | E5: kaba1278 | F5: kaba1278 | G5: kaba1278 | H5: =VLOOKUP(G5,'languoid 4.0'!$A$1:$I$24439,2,FALSE) -> abkh1242 | I5: =VLOOKUP(G5,'languoid 4.0'!$A$1:$I$24439,6,FALSE) -> language | J5: yes | K5: yes | L5: yes | N5: kbd | O5: Exact Match | P5: I'm sure | Q5: Lezgihinka | R5: http://gofile.me/3T2hs/MpnkuHTfp | S5: Track 4 | T5: Harvard Archive of World Music HOLLIS | U5: No secondary function | V5: No | Z5: There is text in associated ethnography that states what type of song this is (this could be in liner notes, it could be in an email from an anthropologist, etc) | AA5: Lezgihinka //HOLLIS NUMBER 990090350310203941 IN HARVARD ARCHIVE OF WORLD MUSIC HOLLIS RELEVANT TEXT IS IN THE LINEAR NOTES PG. 12// | AB5: Much of the music recorded can be divided into two types; male choirs (tracks 1,3 & 5), and instrumental dance music (tracks 2 &4). //HOLLIS NUMBER 990090350310203941 IN HARVARD ARCHIVE OF WORLD MUSIC HOLLIS RELEVANT TEXT IS IN THE LINEAR NOTES PG. 4// | AC5: NA | AD5: File Path Synology: /NHS2/submissions/Central Asia/Before the revolution/4 Audio Track.aiff, https://d16klsh1z1xre7-cloudfront-net.ezp-prod1.hul.harvard.edu/dorp/liner/0/cc14/787d/1000089961-liner.pdf | AE5: I followed the instructions and I have not yet listened to it! | AF5: No | AG5: 1 | AH5: Yes | AJ5: 8/19/2018 19:12:57 | AK5: BSG
A6: =VLOOKUP(H6,Languages!$A$2:$B$430,2,FALSE) -> Abkhaz-Adyge | B6: Dance | C6: Central Asia | D6: Kabardian not found of eHARF | E6: kaba1278 | F6: kaba1278 | G6: kaba1278 | H6: =VLOOKUP(G6,'languoid 4.0'!$A$1:$I$24439,2,FALSE) -> abkh1242 | I6: =VLOOKUP(G6,'languoid 4.0'!$A$1:$I$24439,6,FALSE) -> language | J6: yes | K6: yes | L6: yes | N6: kbd | O6: Exact Match | P6: I'm sure | Q6: Lezgihinka | R6: http://gofile.me/3T2hs/MpnkuHTfp | S6: Track 4 | T6: Harvard Archive of World Music HOLLIS | U6: No secondary function | V6: No | Z6: There is text in associated ethnography that states what type of song this is (this could be in liner notes, it could be in an email from an anthropologist, etc) | AA6: Lezgihinka //HOLLIS NUMBER 990090350310203941 IN HARVARD ARCHIVE OF WORLD MUSIC HOLLIS RELEVANT TEXT IS IN THE LINEAR NOTES PG. 12// | AB6: Much of the music recorded can be divided into two types; male choirs (tracks 1,3 & 5), and instrumental dance music (tracks 2 &4). //HOLLIS NUMBER 990090350310203941 IN HARVARD ARCHIVE OF WORLD MUSIC HOLLIS RELEVANT TEXT IS IN THE LINEAR NOTES PG. 4// | AC6: NA | AD6: File Path Synology: /NHS2/submissions/Central Asia/Before the revolution/4 Audio Track.aiff, https://d16klsh1z1xre7-cloudfront-net.ezp-prod1.hul.harvard.edu/dorp/liner/0/cc14/787d/1000089961-liner.pdf | AE6: I followed the instructions and I have not yet listened to it! | AF6: No | AG6: 1 | AH6: Yes | AJ6: 8/19/2018 19:16:46 | AK6: BSG
A7: =VLOOKUP(H7,Languages!$A$2:$B$430,2,FALSE) -> Abkhaz-Adyge | B7: Mourning | C7: Caucasus | D7: Abkhazia | E7: abkh1244 | F7: abkh1244 | G7: abkh1244 | H7: =VLOOKUP(G7,'languoid 4.0'!$A$1:$I$24439,2,FALSE) -> abkh1242 | I7: =VLOOKUP(G7,'languoid 4.0'!$A$1:$I$24439,6,FALSE) -> language | J7: yes | K7: yes | L7: yes | N7: abk | O7: Exact Match | P7: I'm sure | Q7: Azar | R7: https://search.alexanderstreet.com/preview/work/bibliographic_entity%7Cliner_notes%7C2258560 | S7: Track 7 | T7: Garland Encyclopedia of World Music | U7: No secondary function | V7: No | Z7: There is text in associated ethnography that states what type of song this is (this could be in liner notes, it could be in an email from an anthropologist, etc) | AA7: NA | AB7: Funeral lament in memory of a fallen hero //ON ALEXANDER STREET, IN THE LINER NOTE OF THE ALBUM: The Golden Fleece - Caucasus, Vol. 2: Songs From Abkhazia & Adzharia, PAGE 10// | AC7: NA | AE7: I followed the instructions and I have not yet listened to it! | AF7: Yes | AG7: 6 | AH7: Yes | AJ7: 43259.646 | AK7: AZX
A8: =VLOOKUP(H8,Languages!$A$2:$B$430,2,FALSE) -> Abkhaz-Adyge | B8: Mourning | C8: Caucasus | D8: Abkhazia | E8: abkh1244 | F8: abkh1244 | G8: abkh1244 | H8: =VLOOKUP(G8,'languoid 4.0'!$A$1:$I$24439,2,FALSE) -> abkh1242 | I8: =VLOOKUP(G8,'languoid 4.0'!$A$1:$I$24439,6,FALSE) -> language | J8: yes | K8: yes | L8: yes | N8: abk | O8: Exact Match | P8: I'm sure | Q8: Lament | R8: https://search.alexanderstreet.com/preview/work/bibliographic_entity%7Cliner_notes%7C2258560 | S8: Track 11 | T8: Garland Encyclopedia of World Music | U8: Procession - funeral | V8: No | Z8: There is text in associated ethnography that states what type of song this is (this could be in liner notes, it could be in an email from an anthropologist, etc) | AA8: NA | AB8: The keening over the deceased varies in form and melody. It is either loud calls by women of moan singing by men. Sometimes there is musically organized group-keening performed by men, before the funeral starts [11]. //ON ALEXANDER STREET, IN THE LINER NOTE OF THE ALBUM: The Golden Fleece - Caucasus, Vol. 2: Songs From Abkhazia & Adzharia, PAGE 6// | AC8: NA | AE8: I followed the instructions and I have not yet listened to it! | AF8: Yes | AG8: 6 | AH8: Yes | AJ8: 43259.659 | AK8: AZX
A9: =VLOOKUP(H9,Languages!$A$2:$B$430,2,FALSE) -> Abkhaz-Adyge | B9: Praise | C9: Caucasus | D9: Abkhazia | E9: abkh1244 | F9: abkh1244 | G9: abkh1244 | H9: =VLOOKUP(G9,'languoid 4.0'!$A$1:$I$24439,2,FALSE) -> abkh1242 | I9: =VLOOKUP(G9,'languoid 4.0'!$A$1:$I$24439,6,FALSE) -> language | J9: yes | K9: yes | L9: yes | N9: abk | O9: Exact Match | P9: I'm sure | Q9: Hadzhi Kyaranthyku | R9: https://search.alexanderstreet.com/preview/work/bibliographic_entity%7Cliner_notes%7C2258560 | S9: Track 2 | T9: Garland Encyclopedia of World Music | U9: Story | V9: No | Z9: There is text in associated ethnography that states what type of song this is (this could be in liner notes, it could be in an email from an anthropologist, etc) | AA9: NA | AB9: Heroic song about Hadzhi Kyaranthyku //ON ALEXANDER STREET, IN THE LINER NOTE OF THE ALBUM: The Golden Fleece - Caucasus, Vol. 2: Songs From Abkhazia & Adzharia, PAGE 9// | AC9: NA | AE9: I followed the instructions and I have not yet listened to it! | AF9: Yes | AG9: 6 | AH9: Yes | AJ9: 43259.638 | AK9: AZX
A10: =VLOOKUP(H10,Languages!$A$2:$B$430,2,FALSE) -> Abkhaz-Adyge | B10: Praise | C10: Caucasus | D10: Abkhazia | E10: abkh1244 | F10: abkh1244 | G10: abkh1244 | H10: =VLOOKUP(G10,'languoid 4.0'!$A$1:$I$24439,2,FALSE) -> abkh1242 | I10: =VLOOKUP(G10,'languoid 4.0'!$A$1:$I$24439,6,FALSE) -> language | J10: yes | K10: yes | L10: yes | N10: abk | O10: Exact Match | P10: I'm sure | Q10: Chantari Guagua | R10: https://search.alexanderstreet.com/preview/work/bibliographic_entity%7Cliner_notes%7C2258560 | S10: Track 3 | T10: Garland Encyclopedia of World Music | U10: Story | V10: No | Z10: There is text in associated ethnography that states what type of song this is (this could be in liner notes, it could be in an email from an anthropologist, etc) | AA10: NA | AB10: Heroic epic song about Chantari Guagua //ON ALEXANDER STREET, IN THE LINER NOTE OF THE ALBUM: The Golden Fleece - Caucasus, Vol. 2: Songs From Abkhazia & Adzharia, PAGE 9// | AC10: NA | AE10: I followed the instructions and I have not yet listened to it! | AF10: Yes | AG10: 6 | AH10: Yes | AJ10: 43259.64 | AK10: AZX
A11: =VLOOKUP(H11,Languages!$A$2:$B$430,2,FALSE) -> Abkhaz-Adyge | B11: Praise | C11: Caucasus | D11: Abkhazia | E11: abkh1244 | F11: abkh1244 | G11: abkh1244 | H11: =VLOOKUP(G11,'languoid 4.0'!$A$1:$I$24439,2,FALSE) -> abkh1242 | I11: =VLOOKUP(G11,'languoid 4.0'!$A$1:$I$24439,6,FALSE) -> language | J11: yes | K11: yes | L11: yes | N11: abk | O11: Exact Match | P11: I'm sure | Q11: Ozbak | R11: https://search.alexanderstreet.com/preview/work/bibliographic_entity%7Cliner_notes%7C2258560 | S11: Track 17 | T11: Garland Encyclopedia of World Music | U11: No secondary function | V11: No | Z11: There is text in associated ethnography that states what type of song this is (this could be in liner notes, it could be in an email from an anthropologist, etc) | AA11: NA | AB11: In "Ozbak" [17] the only words that come out clearly are: 'Ozbak is our hero', although every singer knows the legend behind the song. Ozbak, according to this legend, managed to overcome grief after his son had been killed. He did not take revenge on those who killed his son, because he believed that his son was to blame. The heroism of the father is in his high sense of justice. The song ends with a dance to praise the hero for his high moral. //ON ALEXANDER STREET, IN THE LINER NOTE OF THE ALBUM: The Golden Fleece - Caucasus, Vol. 2: Songs From Abkhazia & Adzharia, PAGE 7// | AC11: NA | AE11: I followed the instructions and I have not yet listened to it! | AF11: Yes | AG11: 5 | AH11: Yes | AJ11: 43259.67 | AK11: AZX
A12: =VLOOKUP(H12,Languages!$A$2:$B$430,2,FALSE) -> Abkhaz-Adyge | B12: Procession | C12: Caucasus | D12: Abkhazians | E12: abkh1244 | F12: abkh1244 | G12: abkh1244 | H12: =VLOOKUP(G12,'languoid 4.0'!$A$1:$I$24439,2,FALSE) -> abkh1242 | I12: =VLOOKUP(G12,'languoid 4.0'!$A$1:$I$24439,6,FALSE) -> language | J12: yes | K12: yes | L12: yes | N12: abk | O12: Exact Match | P12: I'm sure | Q12: Wedding Song | R12: https://theglobaljukebox.org/?share=Abkhazia-T5413R01 | S12: NA | T12: Global Jukebox | U12: Wedding | V12: No | Z12: The song is identified as such in its title or label | AA12: Genre: Wedding song //CODING ID 4155 IN GLOBAL JUKEBOX// | AB12: NA | AC12: NA | AE12: I followed the instructions and I have not yet listened to it! | AF12: Yes | AG12: 6 | AH12: Yes | AJ12: 43108.783 | AK12: AZX
A13: =VLOOKUP(H13,Languages!$A$2:$B$430,2,FALSE) -> Abkhaz-Adyge | B13: Procession | C13: Caucasus | D13: Abkhazia | E13: abkh1244 | F13: abkh1244 | G13: abkh1244 | H13: =VLOOKUP(G13,'languoid 4.0'!$A$1:$I$24439,2,FALSE) -> abkh1242 | I13: =VLOOKUP(G13,'languoid 4.0'!$A$1:$I$24439,6,FALSE) -> language | J13: yes | K13: yes | L13: yes | N13: abk | O13: Exact Match | P13: I'm sure | Q13: Azar | R13: https://search.alexanderstreet.com/preview/work/bibliographic_entity%7Cliner_notes%7C2258560 | S13: Track 12 | T13: Garland Encyclopedia of World Music | U13: Funeral | V13: No | Z13: There is text in associated ethnography that states what type of song this is (this could be in liner notes, it could be in an email from an anthropologist, etc) | AA13: NA | AB13: Funeral song //ON ALEXANDER STREET, IN THE LINER NOTE OF THE ALBUM: The Golden Fleece - Caucasus, Vol. 2: Songs From Abkhazia & Adzharia, PAGE 11// | AC13: NA | AE13: I followed the instructions and I have not yet listened to it! | AF13: Yes | AG13: 5 | AH13: Yes | AJ13: 43259.651 | AK13: AZX
A14: =VLOOKUP(H14,Languages!$A$2:$B$430,2,FALSE) -> Abkhaz-Adyge | B14: Procession | C14: Caucasus | D14: Abkhazia | E14: abkh1244 | F14: abkh1244 | G14: abkh1244 | H14: =VLOOKUP(G14,'languoid 4.0'!$A$1:$I$24439,2,FALSE) -> abkh1242 | I14: =VLOOKUP(G14,'languoid 4.0'!$A$1:$I$24439,6,FALSE) -> language | J14: yes | K14: yes | L14: yes | N14: abk | O14: Exact Match | P14: I'm sure | Q14: Azar | R14: https://search.alexanderstreet.com/preview/work/bibliographic_entity%7Cliner_notes%7C2258560 | S14: Track 13 | T14: Garland Encyclopedia of World Music | U14: Horse races | V14: No | Z14: There is text in associated ethnography that states what type of song this is (this could be in liner notes, it could be in an email from an anthropologist, etc) | AA14: NA | AB14: 1. Ritual song at the horse races //ON ALEXANDER STREET, IN THE LINER NOTE OF THE ALBUM: The Golden Fleece - Caucasus, Vol. 2: Songs From Abkhazia & Adzharia, PAGE 11// 2. Azar is also the name of a quite different song that is performed before horse races //ON ALEXANDER STREET, IN THE LINER NOTE OF THE ALBUM: The Golden Fleece - Caucasus, Vol. 2: Songs From Abkhazia & Adzharia, PAGE 6// | AC14: NA | AE14: I followed the instructions and I have not yet listened to it! | AF14: Yes | AG14: 5 | AH14: Yes | AJ14: 43259.655 | AK14: AZX
A15: =VLOOKUP(H15,Languages!$A$2:$B$430,2,FALSE) -> Abkhaz-Adyge | B15: Procession | C15: Caucasus | D15: Abkhazia | E15: abkh1244 | F15: abkh1244 | G15: abkh1244 | H15: =VLOOKUP(G15,'languoid 4.0'!$A$1:$I$24439,2,FALSE) -> abkh1242 | I15: =VLOOKUP(G15,'languoid 4.0'!$A$1:$I$24439,6,FALSE) -> language | J15: yes | K15: yes | L15: yes | N15: abk | O15: Exact Match | P15: I'm sure | Q15: Wedding song | R15: https://search.alexanderstreet.com/preview/work/bibliographic_entity%7Cliner_notes%7C2258560 | S15: Track 22 | T15: Garland Encyclopedia of World Music | U15: Wedding | V15: No | Z15: There is text in associated ethnography that states what type of song this is (this could be in liner notes, it could be in an email from an anthropologist, etc) | AA15: Wedding song //ON ALEXANDER STREET, IN THE LINER NOTE OF THE ALBUM: The Golden Fleece - Caucasus, Vol. 2: Songs From Abkhazia & Adzharia, PAGE 11, TITLE OF SONG 22// | AB15: Ritual song melody //ON ALEXANDER STREET, IN THE LINER NOTE OF THE ALBUM: The Golden Fleece - Caucasus, Vol. 2: Songs From Abkhazia & Adzharia, PAGE 11, DESCRIPTION OF SONG 22// | AC15: NA | AE15: I followed the instructions and I have not yet listened to it! | AF15: Yes | AG15: 4 | AH15: Yes | AJ15: 43259.682 | AK15: AZX
A16: =VLOOKUP(H16,Languages!$A$2:$B$430,2,FALSE) -> Abkhaz-Adyge | B16: Story | C16: Caucasus | D16: Abkhazia | E16: abkh1244 | F16: abkh1244 | G16: abkh1244 | H16: =VLOOKUP(G16,'languoid 4.0'!$A$1:$I$24439,2,FALSE) -> abkh1242 | I16: =VLOOKUP(G16,'languoid 4.0'!$A$1:$I$24439,6,FALSE) -> language | J16: yes | K16: yes | L16: yes | N16: abk | O16: Exact Match | P16: I'm sure | Q16: Zhan Achba | R16: https://search.alexanderstreet.com/preview/work/bibliographic_entity%7Cliner_notes%7C2258560 | S16: Track 14 | T16: Garland Encyclopedia of World Music | U16: No secondary function | V16: No | Z16: There is text in associated ethnography that states what type of song this is (this could be in liner notes, it could be in an email from an anthropologist, etc) | AA16: NA | AB16: This is a very special song about a blind singer who was persecuted for his satirical songs. This person did exist in reality. He died in 1916. //ON ALEXANDER STREET, IN THE LINER NOTE OF THE ALBUM: The Golden Fleece - Caucasus, Vol. 2: Songs From Abkhazia & Adzharia, PAGE 6// | AC16: NA | AE16: I followed the instructions and I have not yet listened to it! | AF16: Yes | AG16: 6 | AH16: Yes | AJ16: 43259.663 | AK16: AZX
A17: =VLOOKUP(H17,Languages!$A$2:$B$430,2,FALSE) -> Abkhaz-Adyge | B17: Story | C17: Caucasus | D17: Abkhazia | E17: abkh1244 | F17: abkh1244 | G17: abkh1244 | H17: =VLOOKUP(G17,'languoid 4.0'!$A$1:$I$24439,2,FALSE) -> abkh1242 | I17: =VLOOKUP(G17,'languoid 4.0'!$A$1:$I$24439,6,FALSE) -> language | J17: yes | K17: yes | L17: yes | N17: abk | O17: Exact Match | P17: I'm sure | Q17: Aiba Huita | R17: https://search.alexanderstreet.com/preview/work/bibliographic_entity%7Cliner_notes%7C2258560 | S17: Track 15 | T17: Garland Encyclopedia of World Music | U17: Praise | V17: No | Z17: There is text in associated ethnography that states what type of song this is (this could be in liner notes, it could be in an email from an anthropologist, etc) | AA17: NA | AB17: The song "Aiba Huita" [15] is about the death of a hero who took revenge over the death of this beloved son but perished in this fight. //ON ALEXANDER STREET, IN THE LINER NOTE OF THE ALBUM: The Golden Fleece - Caucasus, Vol. 2: Songs From Abkhazia & Adzharia, PAGE 6// | AC17: NA | AE17: I followed the instructions and I have not yet listened to it! | AF17: Yes | AG17: 6 | AH17: Yes | AJ17: 43259.665 | AK17: AZX
A18: =VLOOKUP(H18,Languages!$A$2:$B$430,2,FALSE) -> Abkhaz-Adyge | B18: Story | C18: Caucasus | D18: Abkhazia | E18: abkh1244 | F18: abkh1244 | G18: abkh1244 | H18: =VLOOKUP(G18,'languoid 4.0'!$A$1:$I$24439,2,FALSE) -> abkh1242 | I18: =VLOOKUP(G18,'languoid 4.0'!$A$1:$I$24439,6,FALSE) -> language | J18: yes | K18: yes | L18: yes | N18: abk | O18: Exact Match | P18: I'm sure | Q18: Narts | R18: https://search.alexanderstreet.com/preview/work/bibliographic_entity%7Cliner_notes%7C2258560 | S18: Track 20 | T18: Garland Encyclopedia of World Music | U18: Praise | V18: No | Z18: There is text in associated ethnography that states what type of song this is (this could be in liner notes, it could be in an email from an anthropologist, etc) | AA18: NA | AB18: The original song about the Narts [20], performed here on achirpan, tells the story: "In old times there lived people, called 'the great Narts'...The heroic deeds of the Narts are still remembered now". //ON ALEXANDER STREET, IN THE LINER NOTE OF THE ALBUM: The Golden Fleece - Caucasus, Vol. 2: Songs From Abkhazia & Adzharia, PAGE 7 & 8// | AC18: NA | AE18: I followed the instructions and I have not yet listened to it! | AF18: Yes | AG18: 2 | AH18: Yes | AJ18: 43259.68 | AK18: AZX
A19: =VLOOKUP(H19,Languages!$A$2:$B$430,2,FALSE) -> Abkhaz-Adyge | B19: Work | C19: Caucasus | D19: Abkhazia | E19: abkh1244 | F19: abkh1244 | G19: abkh1244 | H19: =VLOOKUP(G19,'languoid 4.0'!$A$1:$I$24439,2,FALSE) -> abkh1242 | I19: =VLOOKUP(G19,'languoid 4.0'!$A$1:$I$24439,6,FALSE) -> language | J19: yes | K19: yes | L19: yes | N19: abk | O19: Exact Match | P19: I'm sure | Q19: Auardin | R19: https://search.alexanderstreet.com/preview/work/bibliographic_entity%7Cliner_notes%7C2258560 | S19: Track 5 | T19: Garland Encyclopedia of World Music | U19: No secondary function | V19: No | Z19: There is text in associated ethnography that states what type of song this is (this could be in liner notes, it could be in an email from an anthropologist, etc) | AA19: NA | AB19: Working song //ON ALEXANDER STREET, IN THE LINER NOTE OF THE ALBUM: The Golden Fleece - Caucasus, Vol. 2: Songs From Abkhazia & Adzharia, PAGE 10// | AC19: NA | AE19: I followed the instructions and I have not yet listened to it! | AF19: Yes | AG19: 6 | AH19: Yes | AJ19: 43259.644 | AK19: AZX
A20: =VLOOKUP(H20,Languages!$A$2:$B$430,2,FALSE) -> Afro-Asiatic | B20: Dance | C20: Eastern Africa | D20: Sidama, Sidamo | E20: sida1246 | F20: sida1246 | G20: sida1246 | H20: =VLOOKUP(G20,'languoid 4.0'!$A$1:$I$24439,2,FALSE) -> afro1255 | I20: =VLOOKUP(G20,'languoid 4.0'!$A$1:$I$24439,6,FALSE) -> language | J20: yes | K20: yes | L20: yes | N20: sid | O20: Exact Match | P20: I'm sure | Q20: Maji Dance Music | R20: https://theglobaljukebox.org/?share=Sidama-T5553R13 | S20: NA | T20: Global Jukebox, CREM, Library of Congress | U20: Feast Song | V20: No | Z20: The song is identified as such in its title or label, There is text in associated ethnography that states what type of song this is (this could be in liner notes, it could be in an email from an anthropologist, etc) | AA20: Dance Song //GLOBAL JUKEBOX, CULT: SIDAMA, AUDIO FILE ID T5553R13// | AB20: Dance song; two-part polyphonic music performed at a feast, hocketing, yodel. //GLOBAL JUKEBOX, CODING ID 9428// | AC20: NA | AD20: Global Jukebox-->Wheel-->East Africa/East African Horn/Highland E. Cushites-->Sidama-->Maji Dance Music | AE20: I followed the instructions and I have not yet listened to it! | AF20: Yes | AG20: 6 | AH20: Yes | AJ20: 43222.515 | AK20: ERA
A21: =VLOOKUP(H21,Languages!$A$2:$B$430,2,FALSE) -> Afro-Asiatic | B21: Dance | C21: Eastern Africa | D21: Ajuran | E21: nort3051 | F21: soma1255 | G21: nort3051 | H21: =VLOOKUP(G21,'languoid 4.0'!$A$1:$I$24439,2,FALSE) -> afro1255 | I21: =VLOOKUP(G21,'languoid 4.0'!$A$1:$I$24439,6,FALSE) -> dialect | J21: no | K21: yes | L21: yes | O21: Exact Match | P21: I'm not sure | Q21: Camel Song and Dance | R21: https://theglobaljukebox.org/?share=Ajuran-T5561R03 | S21: NA | T21: Global Jukebox, Library of Congress | U21: Camel song | V21: No | Z21: The song is identified as such in its title or label | AA21: Dance song //GLOBAL JUKEBOX, CODING ID 9975, AUDIO FILE ID T5561R03// | AB21: NA | AC21: NA | AD21: Global Jukebox-->Wheel-->East Africa/East African Horn/Omotic Peoples-->Ajuran-->Camel Song and Dance | AE21: I followed the instructions and I have not yet listened to it! | AF21: Yes | AG21: 5 | AH21: Yes | AJ21: 43222.562 | AK21: ERA
A22: =VLOOKUP(H22,Languages!$A$2:$B$430,2,FALSE) -> Afro-Asiatic | B22: Dance | C22: Eastern Africa | D22: Bederiya (subset of Baggara/Hemat?) | E22: bath1248 | F22: . | G22: suda1236 | H22: =VLOOKUP(G22,'languoid 4.0'!$A$1:$I$24439,2,FALSE) -> afro1255 | I22: =VLOOKUP(G22,'languoid 4.0'!$A$1:$I$24439,6,FALSE) -> language | J22: no | K22: . | L22: . | O22: Exact Match | P22: I'm sure | Q22: Merdum Song | R22: https://theglobaljukebox.org/?share=Bederiya-T5625R09m | S22: NA | T22: Global Jukebox | U22: Dance | V22: No | Z22: There is text in associated ethnography that states what type of song this is (this could be in liner notes, it could be in an email from an anthropologist, etc) | AA22: Merdum Song //GLOBAL JUKEBOX, CODING ID 4211, SONG FIELD// | AB22: Genre: Dance song; Description: Dance with chorus //GLOBAL JUKEBOX, CODING ID 4211// | AC22: NA | AD22: click on green checklist or song title in lower right corner | AE22: Earlier today, I heard maybe a second fading in as it autoplayed after the previous track | AF22: Yes | AG22: 5 | AH22: Yes | AJ22: 4/16/2018 12:22:14 | AK22: MJW
A23: =VLOOKUP(H23,Languages!$A$2:$B$430,2,FALSE) -> Afro-Asiatic | B23: Dance | C23: Northern Africa | D23: Gourara | E23: gour1247 | F23: berb1260 | G23: gour1247 | H23: =VLOOKUP(G23,'languoid 4.0'!$A$1:$I$24439,2,FALSE) -> afro1255 | I23: =VLOOKUP(G23,'languoid 4.0'!$A$1:$I$24439,6,FALSE) -> dialect | J23: no | K23: yes | L23: yes | O23: Exact Match | P23: I'm sure | Q23: Dance with qarqabou | R23: http://www.worldcat.org/oclc/34555452 | S23: Track 7 | T23: NHS 1.0 | V23: No | AA23: 6 | AB23: 6 | AC23: NA | AJ23: 43102.753 | AK23: SDA
A24: =VLOOKUP(H24,Languages!$A$2:$B$430,2,FALSE) -> Afro-Asiatic | B24: Dance | C24: Northern Africa | D24: Atlas Berbers: Shilha / Shluh | E24: cent2194 | F24: berb1260 | G24: cent2194 | H24: =VLOOKUP(G24,'languoid 4.0'!$A$1:$I$24439,2,FALSE) -> afro1255 | I24: =VLOOKUP(G24,'languoid 4.0'!$A$1:$I$24439,6,FALSE) -> language | J24: no | K24: yes | L24: yes | N24: tzm | O24: Exact Match | P24: I'm sure | Q24: Dance Song | R24: http://media.theglobaljukebox.org/audio/T40010R03.mp3 | S24: NA | T24: Global Jukebox | U24: No secondary function | V24: No | Z24: The song is identified as such in its title or label, There is text in associated ethnography that states what type of song this is (this could be in liner notes, it could be in an email from an anthropologist, etc) | AA24: Dance song //GLOBAL JUKEBOX CODING ID 3295 GENRE// | AB24: Male leader in alternation with mixed chorus over bowed lute and percussion //GLOBAL JUKEBOX CODING ID 3295 DESCRIPTION// | AC24: NA | AE24: I followed the instructions and I have not yet listened to it! | AF24: Yes | AG24: 4 | AH24: Yes | AJ24: 4/19/2018 11:12:26 | AK24: MJW
A25: =VLOOKUP(H25,Languages!$A$2:$B$430,2,FALSE) -> Afro-Asiatic | B25: Dance | C25: Northern Africa | D25: Morocco Berbers | E25: cent2194 | F25: riff1234 | G25: cent2194 | H25: =VLOOKUP(G25,'languoid 4.0'!$A$1:$I$24439,2,FALSE) -> afro1255 | I25: =VLOOKUP(G25,'languoid 4.0'!$A$1:$I$24439,6,FALSE) -> language | J25: no | K25: yes | L25: yes | N25: tzm | O25: Exact Match | P25: I'm sure | Q25: Line Dance | R25: http://media.theglobaljukebox.org/audio/T5521R51.mp3 | S25: NA | T25: Global Jukebox | U25: No secondary function | V25: No | Z25: The song is identified as such in its title or label | AA25: Dance song; line dance //GLOBAL JUKEBOX CODING ID 9247 GENRE// | AB25: NA | AC25: NA | AE25: I followed the instructions and I have not yet listened to it! | AF25: Yes | AG25: 4 | AH25: Yes | AJ25: 4/19/2018 11:16:06 | AK25: MJW
A26: =VLOOKUP(H26,Languages!$A$2:$B$430,2,FALSE) -> Afro-Asiatic | B26: Dance | C26: Northern Africa | D26: Tuareg | E26: tuar1240 | F26: tuar1240 | G26: tuar1240 | H26: =VLOOKUP(G26,'languoid 4.0'!$A$1:$I$24439,2,FALSE) -> afro1255 | I26: =VLOOKUP(G26,'languoid 4.0'!$A$1:$I$24439,6,FALSE) -> family | J26: yes | K26: yes | L26: yes | N26: tmh | O26: Most Common Subfamily | P26: I'm sure | Q26: Tohimo Dance | R26: http://media.theglobaljukebox.org/audio/T45022.mp3 | S26: NA | T26: Global Jukebox | U26: No secondary function | V26: No | Z26: The song is identified as such in its title or label | AA26: Dance song //GLOBAL JUKEBOX CODING ID 955 GENRE// | AB26: NA | AC26: NA | AE26: I followed the instructions and I have not yet listened to it! | AF26: Yes | AG26: 4 | AH26: Yes | AJ26: 4/19/2018 11:20:29 | AK26: MJW
A27: =VLOOKUP(H27,Languages!$A$2:$B$430,2,FALSE) -> Afro-Asiatic | B27: Dance | C27: Northern Africa | D27: Tuareg (Morocco Berbers) | E27: hogg1238 | F27: stan1290 | G27: tuar1240 | H27: =VLOOKUP(G27,'languoid 4.0'!$A$1:$I$24439,2,FALSE) -> afro1255 | I27: =VLOOKUP(G27,'languoid 4.0'!$A$1:$I$24439,6,FALSE) -> family | J27: no | K27: no | L27: no | O27: Exact Match | P27: I'm sure | Q27: Suite de ghedras de Goulimine | R27: http://www.worldcat.org/oclc/61711547 | S27: Side B | T27: Global Jukebox, Alan Lomax Collection | U27: Ritual | V27: No | Z27: The song is identified as such in its title or label, There is text in associated ethnography that states what type of song this is (this could be in liner notes, it could be in an email from an anthropologist, etc) | AA27: Ritual song; dance song; religious song; trance song //GLOBAL JUKEBOX CODING ID 9602 GENRE// | AB27: The guedra ritual dance serves as a blessing for friends or married people or to the community, or to submit the self to God; hypnotic and increasingly frenzied dance performed by solo female //GLOBAL JUKEBOX CODING ID 9602 DESCRIPTION// | AC27: NA | AD27: Listed in WorldCat as four tracks: Ghedra douce, Ghedra syncopee, Ghedra endiablee, Ghedra passionnee. | AE27: I followed the instructions and I have not yet listened to it! | AF27: Yes | AG27: 4 | AH27: Yes | AI27: Audio not available on Global Jukebox. | AJ27: 43286.453 | AK27: MJW
A28: =VLOOKUP(H28,Languages!$A$2:$B$430,2,FALSE) -> Afro-Asiatic | B28: Dance | C28: Northern Africa | D28: Atlas Berbers: Shilha/Shluh/Chleuh, Haha tribe | E28: cent2194 | F28: berb1260 | G28: cent2194 | H28: =VLOOKUP(G28,'languoid 4.0'!$A$1:$I$24439,2,FALSE) -> afro1255 | I28: =VLOOKUP(G28,'languoid 4.0'!$A$1:$I$24439,6,FALSE) -> language | J28: no | K28: yes | L28: yes | N28: tzm | O28: Exact Match | P28: I'm sure | Q28: Ahouach of Zaouia | R28: http://media.theglobaljukebox.org/audio/T40010R04.mp3 | S28: NA | T28: Global Jukebox | U28: No secondary function | V28: No | Z28: The song is identified as such in its title or label, There is text in associated ethnography that states what type of song this is (this could be in liner notes, it could be in an email from an anthropologist, etc) | AA28: Dance song; circle dance //GLOBAL JUKEBOX CODING ID 3294 GENRE// | AB28: Ahouach; Circle Dance; from Southern Morocco; men form circle and play bendir drums, while women shuffle in a larger circle around them //GLOBAL JUKEBOX CODING ID 3294 DESCRIPTION// | AC28: NA | AE28: I followed the instructions and I have not yet listened to it! | AF28: Yes | AG28: 5 | AH28: Yes | AJ28: 43286.496 | AK28: MJW
A29: =VLOOKUP(H29,Languages!$A$2:$B$430,2,FALSE) -> Afro-Asiatic | B29: Dance | C29: Northern Africa | D29: Atlas Berbers: Shilha/Shluh/Chleuh, Haha tribe | E29: cent2194 | F29: berb1260 | G29: cent2194 | H29: =VLOOKUP(G29,'languoid 4.0'!$A$1:$I$24439,2,FALSE) -> afro1255 | I29: =VLOOKUP(G29,'languoid 4.0'!$A$1:$I$24439,6,FALSE) -> language | J29: no | K29: yes | L29: yes | N29: tzm | O29: Exact Match | P29: I'm sure | Q29: Ahouach Ded Ida | R29: http://media.theglobaljukebox.org/audio/T40010R01.mp3 | S29: NA | T29: Global Jukebox | U29: No secondary function | V29: No | Z29: The song is identified as such in its title or label, There is text in associated ethnography that states what type of song this is (this could be in liner notes, it could be in an email from an anthropologist, etc) | AA29: Dance song; circle dance //GLOBAL JUKEBOX CODING ID 3297 GENRE// | AB29: Ahouach; Circle Dance; from Southern Morocco; men form circle and play bendir drums, while women shuffle in a larger circle around them //GLOBAL JUKEBOX CODING ID 3297 DESCRIPTION// | AC29: NA | AE29: I followed the instructions and I have not yet listened to it! | AF29: Yes | AG29: 3 | AH29: Yes | AJ29: 43286.499 | AK29: MJW
A30: =VLOOKUP(H30,Languages!$A$2:$B$430,2,FALSE) -> Afro-Asiatic | B30: Dance | C30: Northern Africa | D30: Atlas Berbers: Shilha/Shluh/Chleuh, Haha tribe | E30: cent2194 | F30: berb1260 | G30: cent2194 | H30: =VLOOKUP(G30,'languoid 4.0'!$A$1:$I$24439,2,FALSE) -> afro1255 | I30: =VLOOKUP(G30,'languoid 4.0'!$A$1:$I$24439,6,FALSE) -> language | J30: no | K30: yes | L30: yes | N30: tzm | O30: Exact Match | P30: I'm sure | Q30: Antiphonal song | R30: http://media.theglobaljukebox.org/audio/T40031R02.mp3 | S30: NA | T30: Global Jukebox | U30: No secondary function | V30: No | Z30: The song is identified as such in its title or label, There is text in associated ethnography that states what type of song this is (this could be in liner notes, it could be in an email from an anthropologist, etc) | AA30: Dance song //GLOBAL JUKEBOX CODING ID 3290 GENRE// | AB30: Women dance and sing around the circle of male drummers //GLOBAL JUKEBOX CODING ID 3290 DESCRIPTION// | AC30: NA | AE30: I followed the instructions and I have not yet listened to it! | AF30: Yes | AG30: 4 | AH30: Yes | AJ30: 43286.501 | AK30: MJW
A31: =VLOOKUP(H31,Languages!$A$2:$B$430,2,FALSE) -> Afro-Asiatic | B31: Dance | C31: Northern Africa | D31: Atlas Berbers: Shilha/Shluh/Chleuh, Haha tribe | E31: cent2194 | F31: berb1260 | G31: cent2194 | H31: =VLOOKUP(G31,'languoid 4.0'!$A$1:$I$24439,2,FALSE) -> afro1255 | I31: =VLOOKUP(G31,'languoid 4.0'!$A$1:$I$24439,6,FALSE) -> language | J31: no | K31: yes | L31: yes | N31: tzm | O31: Exact Match | P31: I'm sure | Q31: Great Ahouach of Telouet | R31: http://media.theglobaljukebox.org/audio/T40030R01.mp3 | S31: NA | T31: Global Jukebox | U31: No secondary function | V31: No | Z31: The song is identified as such in its title or label, There is text in associated ethnography that states what type of song this is (this could be in liner notes, it could be in an email from an anthropologist, etc) | AA31: Dance song; festival song //GLOBAL JUKEBOX CODING ID 3293 GENRE// | AB31: Festival dance //GLOBAL JUKEBOX CODING ID 3293 DESCRIPTION// | AC31: NA | AE31: I followed the instructions and I have not yet listened to it! | AF31: Yes | AG31: 4 | AH31: Yes | AJ31: 43286.503 | AK31: MJW
A32: =VLOOKUP(H32,Languages!$A$2:$B$430,2,FALSE) -> Afro-Asiatic | B32: Dance | C32: Northern Africa | D32: Atlas Berbers: Shilha/Shluh/Chleuh, Haha tribe | E32: cent2194 | F32: berb1260 | G32: cent2194 | H32: =VLOOKUP(G32,'languoid 4.0'!$A$1:$I$24439,2,FALSE) -> afro1255 | I32: =VLOOKUP(G32,'languoid 4.0'!$A$1:$I$24439,6,FALSE) -> language | J32: no | K32: yes | L32: yes | N32: tzm | O32: Exact Match | P32: I'm sure | Q32: Ahmeilou | R32: http://www.worldcat.org/oclc/3100954 | S32: Disc 1, Track 1 | T32: Global Jukebox | U32: No secondary function | V32: No | Z32: The song is identified as such in its title or label, There is text in associated ethnography that states what type of song this is (this could be in liner notes, it could be in an email from an anthropologist, etc) | AA32: Dance song //GLOBAL JUKEBOX CODING ID 1588 GENRE// | AB32: //PAGE 2, ITEM 1, IN LIBRARY OF CONGRESS NOTES FOR RECORDING LABORATORY AFS L63 AND L64 https://www.loc.gov/folklife/LP/Morocco_opt.pdf// | AC32: NA | AE32: I followed the instructions and I have not yet listened to it! | AF32: No | AG32: 3 | AH32: Yes | AI32: Global Jukebox uses the title "Prelude and Dance" and does not include audio. | AJ32: 43286.523 | AK32: MJW
A33: =VLOOKUP(H33,Languages!$A$2:$B$430,2,FALSE) -> Afro-Asiatic | B33: Dance | C33: Southeastern Europe | D33: Dervish, Sufi | E33: nucl1301 | F33: arab1395 | G33: arab1395 | H33: =VLOOKUP(G33,'languoid 4.0'!$A$1:$I$24439,2,FALSE) -> afro1255 | I33: =VLOOKUP(G33,'languoid 4.0'!$A$1:$I$24439,6,FALSE) -> family | J33: no | K33: no | L33: no | N33: tur | O33: Exact Match | P33: I'm sure | Q33: Ode by Ahmad al-'Alawi | R33: https://theglobaljukebox.org/?share=Dervish-T5483R23 | S33: Disc 1, Track 5 | T33: Global Jukebox, Smithsonian Folkways | U33: Religious | V33: No | Z33: The song is identified as such in its title or label, There is text in associated ethnography that states what type of song this is (this could be in liner notes, it could be in an email from an anthropologist, etc) | AA33: Religious Song// GLOBAL JUKEBOX, CODING ID 994 // | AB33: Ode by Ahmad Al-'Alawi, opening with the Shahadah, that is the ritual formula La ilaha illa' Llah (d. 1934), repeated here 3 times, Muhammadun rasulu Llah, Islamic Liturgy: Song and Dance at a Meeting of Dervishes. // GLOBAL JUKEBOX, CODING ID 994 // | AC33: NA | AE33: I followed the instructions and I have not yet listened to it! | AF33: Yes | AG33: 6 | AH33: Yes | AJ33: 6/13/2018 18:41:02 | AK33: JCVL
A34: =VLOOKUP(H34,Languages!$A$2:$B$430,2,FALSE) -> Afro-Asiatic | B34: Dance | C34: Southeastern Europe | D34: Dervish, Turkey | E34: nucl1301 | F34: arab1395 | G34: arab1395 | H34: =VLOOKUP(G34,'languoid 4.0'!$A$1:$I$24439,2,FALSE) -> afro1255 | I34: =VLOOKUP(G34,'languoid 4.0'!$A$1:$I$24439,6,FALSE) -> family | J34: no | K34: no | L34: no | N34: tur | O34: Exact Match | P34: I'm sure | Q34: End of the Tarhib/ Invocation of the Divine Name/ The Sacred Dance | R34: https://theglobaljukebox.org/?share=Dervish-T5483R26 | S34: Disc 1, Track 15 | T34: Global Jukebox, Smithsonian Folkways | U34: No secondary function | V34: No | Z34: The song is identified as such in its title or label | AA34: Religious song; Quranic text//GLOBAL JUKEBOX CODING: 997// | AB34: End of the Tarhib (Liturgy), Invocation of the Divine Name, The Sacred Dance, Al-Hadrah (The Presence); words of Blessing upon the Prophet; Quran, XXXIII, v. 23//GLOBAL JUKEBOX CODING: 997// | AC34: NA | AE34: I followed the instructions and I have not yet listened to it! | AF34: Yes | AG34: 6 | AH34: Yes | AJ34: 6/13/2018 20:39:18 | AK34: JCVL
A35: =VLOOKUP(H35,Languages!$A$2:$B$430,2,FALSE) -> Afro-Asiatic | B35: Healing | C35: Central Africa | D35: Kuyu (location: Fort-Rousset, Ouando, Congo) | E35: . | F35: . | G35: nucl1736 | H35: =VLOOKUP(G35,'languoid 4.0'!$A$1:$I$24439,2,FALSE) -> afro1255 | I35: =VLOOKUP(G35,'languoid 4.0'!$A$1:$I$24439,6,FALSE) -> family | J35: . | K35: . | L35: . | N35: #N/A | O35: Unknown | Q35: CHANT DE GUERISON IKANGO | R35: https://archives.crem-cnrs.fr/archives/items/CNRSMH_I_1974_013_004_06/ | S35: Disc 2, Track 14 | T35: CREM | U35: No secondary function | V35: No | Z35: The song is identified as such in its title or label, There is text in associated ethnography that states what type of song this is (this could be in liner notes, it could be in an email from an anthropologist, etc) | AA35: CHANT DE GUERISON IKANGO//CODING ID CNRSMH_I_1974_013_004_06 IN CREM, RELEVANT TEXT IS IN THE TITLE FIELD// | AB35: Guérison//CODING ID CNRSMH_I_1974_013_004_06 IN CREM, RELEVANT TEXT IS IN THE KEYWORDS FIELD// | AC35: NA | AE35: I followed the instructions and I have not yet listened to it! | AF35: Yes | AG35: 3 | AH35: Yes | AJ35: 8/24/2018 14:06:18 | AK35: NCM
A36: =VLOOKUP(H36,Languages!$A$2:$B$430,2,FALSE) -> Afro-Asiatic | B36: Healing | C36: Eastern Africa | D36: Amhara | E36: amha1245 | F36: amha1245 | G36: amha1245 | H36: =VLOOKUP(G36,'languoid 4.0'!$A$1:$I$24439,2,FALSE) -> afro1255 | I36: =VLOOKUP(G36,'languoid 4.0'!$A$1:$I$24439,6,FALSE) -> language | J36: yes | K36: yes | L36: yes | N36: amh | O36: Exact Match | P36: I'm sure | Q36: My Medicine | R36: https://theglobaljukebox.org/?share=Amhara-T5596R07 | S36: NA | T36: Global Jukebox, Library of Congress | U36: No secondary function | V36: No | Z36: The song is identified as such in its title or label | AA36: Healing song //GLOBAL JUKEBOX, CODING ID 3452, AUDIO FILE ID T5596R07// | AB36: NA | AC36: NA | AD36: Global Jukebox-->Wheel-->East Africa/Highland Ethiopia/Ethiopian Semites-->Amhara-->My Medicine | AE36: I followed the instructions and I have not yet listened to it! | AF36: Yes | AG36: 4 | AH36: Yes | AJ36: 43222.57 | AK36: ERA
A37: =VLOOKUP(H37,Languages!$A$2:$B$430,2,FALSE) -> Afro-Asiatic | B37: Healing | C37: Eastern Africa | D37: Amhara | E37: amha1245 | F37: amha1245 | G37: amha1245 | H37: =VLOOKUP(G37,'languoid 4.0'!$A$1:$I$24439,2,FALSE) -> afro1255 | I37: =VLOOKUP(G37,'languoid 4.0'!$A$1:$I$24439,6,FALSE) -> language | J37: yes | K37: yes | L37: yes | N37: amh | O37: Exact Match | P37: I'm sure | Q37: My Medicine 2 | R37: https://theglobaljukebox.org/?share=Amhara-T5596R08 | S37: NA | T37: Global Jukebox | U37: Medicine song | V37: No | Z37: The song is identified as such in its title or label | AA37: Healing Song //GLOBAL JUKEBOX, MY MEDICINE 2, CODING ID 3453, AUDIO FILE ID T5596R08// | AB37: NA | AC37: NA | AD37: Global Jukebox-->Wheel-->East Africa/Highland Ethiopia/Ethiopian Semites-->Amhara-->My Medicine 2 | AE37: I followed the instructions and I have not yet listened to it! | AF37: Yes | AG37: 6 | AH37: Yes | AJ37: 43253.722 | AK37: ERA
A38: =VLOOKUP(H38,Languages!$A$2:$B$430,2,FALSE) -> Afro-Asiatic | B38: Healing | C38: Northern Africa | D38: Tunisians | E38: tuni1260 | F38: stan1318 | G38: tuni1260 | H38: =VLOOKUP(G38,'languoid 4.0'!$A$1:$I$24439,2,FALSE) -> afro1255 | I38: =VLOOKUP(G38,'languoid 4.0'!$A$1:$I$24439,6,FALSE) -> dialect | J38: no | K38: yes | L38: yes | O38: Exact Match | P38: I'm sure | Q38: Sīdī bū ra's el-‘ajmī | R38: http://www.worldcat.org/oclc/758855535 | S38: Track 4 | T38: NHS 1.0 | V38: No | AA38: 20 | AB38: 8-9, 10, 12-15,17-18 | AC38: 10, 14 | AJ38: 43102.76 | AK38: MDS
A39: =VLOOKUP(H39,Languages!$A$2:$B$430,2,FALSE) -> Afro-Asiatic | B39: Healing | C39: Northern Africa | D39: Gnawa | E39: . | F39: arab1395 | G39: arab1395 | H39: =VLOOKUP(G39,'languoid 4.0'!$A$1:$I$24439,2,FALSE) -> afro1255 | I39: =VLOOKUP(G39,'languoid 4.0'!$A$1:$I$24439,6,FALSE) -> family | J39: no | K39: . | L39: . | N39: #N/A | O39: Unknown | Q39: Fatha | R39: http://www.worldcat.org/oclc/25457764 | S39: Side A, Band 3 | T39: WorldCat | U39: No secondary function | V39: No | Z39: There is text in associated ethnography that states what type of song this is (this could be in liner notes, it could be in an email from an anthropologist, etc) | AA39: NA | AB39: The remaining Band 4 [should be 3] contains Fatha, a prayer, since the Gnawas, in addition to providing entertainment through their music and dance on the streets of towns and villages, possess magical power to cure certain diseases and mental disorders. //ETHNOMUSICOLOGY, VOL 19 NO 1, PAGE 155, RECORD REVIEW http://www.jstor.org.ezp-prod1.hul.harvard.edu/stable/849760// | AC39: NA | AH39: No | AJ39: 43409.57 | AK39: MJW
A40: =VLOOKUP(H40,Languages!$A$2:$B$430,2,FALSE) -> Afro-Asiatic | B40: Love | C40: Eastern Africa | D40: Amhara | E40: amha1245 | F40: amha1245 | G40: amha1245 | H40: =VLOOKUP(G40,'languoid 4.0'!$A$1:$I$24439,2,FALSE) -> afro1255 | I40: =VLOOKUP(G40,'languoid 4.0'!$A$1:$I$24439,6,FALSE) -> language | J40: yes | K40: yes | L40: yes | N40: amh | O40: Exact Match | P40: I'm sure | Q40: Shemonmuanaye | R40: http://www.worldcat.org/oclc/2135349 | S40: Side 2, Track 1 | T40: NHS 1.0 | V40: No | AA40: 7 | AB40: 7 | AC40: NA | AJ40: 43102.764 | AK40: CMB
...

Sheet languoid 4.0
A1: id | B1: family_id | C1: parent_id | D1: name | E1: bookkeeping | F1: level | G1: latitude | H1: longitude | I1: iso639P3code | J1: description | K1: markup_description | L1: child_family_count | M1: child_language_count | N1: child_dialect_count | O1: country_ids
A2: 3adt1234 | B2: afro1255 | C2: nort3292 | D2: 3Ad-Tekles | E2: FALSE | F2: dialect | L2: 0 | M2: 0 | N2: 0
A3: aala1237 | B3: aust1307 | C3: ramo1244 | D3: Aalawa | E3: FALSE | F3: dialect | L3: 0 | M3: 0 | N3: 0
A4: aant1238 | B4: nucl1709 | C4: nort2920 | D4: Aantantara | E4: FALSE | F4: dialect | L4: 0 | M4: 0 | N4: 0
A5: aari1238 | B5: sout2845 | C5: ahkk1235 | D5: Aari-Gayil | E5: FALSE | F5: family | I5: aiz | L5: 0 | M5: 2 | N5: 0
A6: aari1239 | B6: sout2845 | C6: aari1238 | D6: Aari | E6: FALSE | F6: language | G6: 5.95034 | H6: 36.5721 | I6: aiw | L6: 0 | M6: 0 | N6: 0 | O6: ET
A7: aari1240 | B7: book1242 | C7: book1242 | D7: Aariya | E7: TRUE | F7: language | I7: aay | L7: 0 | M7: 0 | N7: 0 | O7: IN
A8: aasa1238 | B8: afro1255 | C8: unun9872 | D8: Aasax | E8: FALSE | F8: language | G8: -4.00679 | H8: 36.8648 | I8: aas | L8: 0 | M8: 0 | N8: 0 | O8: TZ
A9: aasd1234 | B9: indo1319 | C9: ferr1240 | D9: Aasdring | E9: FALSE | F9: dialect | L9: 0 | M9: 0 | N9: 0
A10: aata1238 | B10: nucl1709 | C10: sout2943 | D10: Aatasaara | E10: FALSE | F10: dialect | L10: 0 | M10: 0 | N10: 0
A11: abaa1238 | B11: sino1245 | C11: nort3305 | D11: Rngaba | E11: FALSE | F11: dialect | L11: 0 | M11: 0 | N11: 0
A12: abab1239 | B12: afro1255 | C12: beja1238 | D12: Ababda | E12: FALSE | F12: dialect | L12: 0 | M12: 0 | N12: 0
A13: abab1240 | B13: atla1278 | C13: narr1281 | D13: Ababuan | E13: FALSE | F13: family | L13: 13 | M13: 22 | N13: 29
A14: abad1240 | B14: abkh1242 | C14: adyg1241 | D14: Abadzex | E14: FALSE | F14: dialect | L14: 0 | M14: 0 | N14: 0
A15: abad1241 | B15: aust1307 | C15: west2850 | D15: Abadi | E15: FALSE | F15: language | G15: -9.03389 | H15: 146.992 | I15: kbt | L15: 0 | M15: 0 | N15: 0 | O15: PG
A16: abag1245 | B16: nucl1709 | C16: unun9976 | D16: Abaga | E16: FALSE | F16: language | G16: -6.12028 | H16: 145.665 | I16: abg | L16: 0 | M16: 0 | N16: 0 | O16: PG
A17: abai1239 | B17: aust1307 | C17: lund1271 | D17: Abai | E17: FALSE | F17: dialect | L17: 0 | M17: 0 | N17: 0
A18: abai1240 | B18: aust1307 | C18: pait1248 | D18: Abai Sungai | E18: FALSE | F18: language | G18: 5.55394 | H18: 118.306 | I18: abf | L18: 0 | M18: 0 | N18: 0 | O18: MY
A19: abai1241 | B19: aust1307 | C19: muru1275 | D19: Abai Tubu-Abai Sembuak | E19: FALSE | F19: language | L19: 0 | M19: 0 | N19: 0 | O19: MY
A20: abak1242 | B20: atla1278 | C20: anaa1238 | D20: Abak | E20: FALSE | F20: dialect | L20: 0 | M20: 0 | N20: 0
A21: abak1243 | B21: aust1307 | C21: ilon1239 | D21: Abaka | E21: FALSE | F21: dialect | L21: 0 | M21: 0 | N21: 0
A22: abal1238 | B22: yele1255 | C22: yele1255 | D22: Abaletti | E22: FALSE | F22: dialect | L22: 0 | M22: 0 | N22: 0
A23: abam1239 | B23: east2503 | C23: wipi1242 | D23: Abam | E23: FALSE | F23: dialect | L23: 0 | M23: 0 | N23: 0
A24: aban1242 | B24: atla1278 | C24: aban1244 | D24: Abanyom | E24: FALSE | F24: language | G24: 6.30619 | H24: 8.63055 | I24: abm | L24: 0 | M24: 0 | N24: 0 | O24: NG
A25: aban1243 | B25: quec1387 | C25: east2551 | D25: Abancay | E25: FALSE | F25: dialect | L25: 0 | M25: 0 | N25: 0
A26: aban1244 | B26: atla1278 | C26: bako1254 | D26: Abanyom-Ekajuk | E26: FALSE | F26: family | L26: 0 | M26: 3 | N26: 0
A27: abar1238 | B27: atla1278 | C27: sout3152 | D27: Mungbam | E27: FALSE | F27: language | G27: 6.5805 | H27: 10.2267 | I27: mij | L27: 0 | M27: 0 | N27: 0 | O27: CM
A28: abau1245 | B28: sepi1257 | C28: sepi1257 | D28: Abau | E28: FALSE | F28: language | G28: -3.97222 | H28: 141.324 | I28: aau | L28: 0 | M28: 0 | N28: 0 | O28: PG
A29: abaw1238 | B29: atla1278 | C29: gupa1248 | D29: Abawa | E29: FALSE | F29: dialect | L29: 0 | M29: 0 | N29: 0
A30: abay1238 | B30: atla1278 | C30: agwa1247 | D30: Abayongo | E30: FALSE | F30: dialect | L30: 0 | M30: 0 | N30: 0
A31: abaz1241 | B31: abkh1242 | C31: abkh1243 | D31: Abaza | E31: FALSE | F31: language | G31: 41.1214 | H31: 42.7273 | I31: abq | L31: 0 | M31: 0 | N31: 3 | O31: RU TR
A32: abbe1238 | B32: atla1278 | C32: abee1242 | D32: Abbey-Ve | E32: FALSE | F32: dialect | L32: 0 | M32: 0 | N32: 0
A33: abbr1238 | B33: indo1319 | C33: sout3309 | D33: Abbruzzesi | E33: FALSE | F33: dialect | L33: 0 | M33: 0 | N33: 0
A34: abda1238 | B34: afro1255 | C34: soqo1240 | D34: 'Abd Al-Kuri | E34: FALSE | F34: dialect | L34: 0 | M34: 0 | N34: 0
A35: abed1238 | B35: cent2225 | C35: lugb1240 | D35: Abedju-Azaki | E35: FALSE | F35: dialect | L35: 0 | M35: 0 | N35: 0
A36: abee1242 | B36: atla1278 | C36: agne1238 | D36: Ab√© | E36: FALSE | F36: language | G36: 5.59682 | H36: -4.38497 | I36: aba | L36: 0 | M36: 0 | N36: 4 | O36: CI
A37: abee1243 | B37: atla1278 | C37: anyi1245 | D37: Abe (Anyin) | E37: FALSE | F37: dialect | L37: 0 | M37: 0 | N37: 0
A38: abel1234 | B38: aust1307 | C38: samb1319 | D38: Abellen-Botolan | E38: FALSE | F38: family | L38: 0 | M38: 2 | N38: 2
A39: aben1247 | B39: sino1245 | C39: garo1247 | D39: Abeng | E39: FALSE | F39: dialect | L39: 0 | M39: 0 | N39: 0
A40: aben1248 | B40: sino1245 | C40: garo1247 | D40: A'beng | E40: FALSE | F40: dialect | L40: 0 | M40: 0 | N40: 0
...

Sheet Languages
A1: ID | B1: Name | C1: Latitude | D1: Longitude
A2: atla1278 | B2: =HYPERLINK("https://glottolog.org/resource/languoid/id/atla1278","Atlantic-Congo") -> Atlantic-Congo
A3: aust1307 | B3: =HYPERLINK("https://glottolog.org/resource/languoid/id/aust1307","Austronesian") -> Austronesian
A4: indo1319 | B4: =HYPERLINK("https://glottolog.org/resource/languoid/id/indo1319","Indo-European") -> Indo-European
A5: sino1245 | B5: =HYPERLINK("https://glottolog.org/resource/languoid/id/sino1245","Sino-Tibetan") -> Sino-Tibetan
A6: book1242 | B6: =HYPERLINK("https://glottolog.org/resource/languoid/id/book1242","Bookkeeping") -> Bookkeeping
A7: afro1255 | B7: =HYPERLINK("https://glottolog.org/resource/languoid/id/afro1255","Afro-Asiatic") -> Afro-Asiatic
A8: nucl1709 | B8: =HYPERLINK("https://glottolog.org/resource/languoid/id/nucl1709","Nuclear Trans New Guinea") -> Nuclear Trans New Guinea
A9: pama1250 | B9: =HYPERLINK("https://glottolog.org/resource/languoid/id/pama1250","Pama-Nyungan") -> Pama-Nyungan
A10: sign1238 | B10: =HYPERLINK("https://glottolog.org/resource/languoid/id/sign1238","Sign Language") -> Sign Language
A11: otom1299 | B11: =HYPERLINK("https://glottolog.org/resource/languoid/id/otom1299","Otomanguean") -> Otomanguean
A12: aust1305 | B12: =HYPERLINK("https://glottolog.org/resource/languoid/id/aust1305","Austroasiatic") -> Austroasiatic
A13: uncl1493 | B13: =HYPERLINK("https://glottolog.org/resource/languoid/id/uncl1493","Unclassifiable") -> Unclassifiable
A14: taik1256 | B14: =HYPERLINK("https://glottolog.org/resource/languoid/id/taik1256","Tai-Kadai") -> Tai-Kadai
A15: drav1251 | B15: =HYPERLINK("https://glottolog.org/resource/languoid/id/drav1251","Dravidian") -> Dravidian
A16: pidg1258 | B16: =HYPERLINK("https://glottolog.org/resource/languoid/id/pidg1258","Pidgin") -> Pidgin
A17: araw1281 | B17: =HYPERLINK("https://glottolog.org/resource/languoid/id/araw1281","Arawakan") -> Arawakan
A18: mand1469 | B18: =HYPERLINK("https://glottolog.org/resource/languoid/id/mand1469","Mande") -> Mande
A19: tupi1275 | B19: =HYPERLINK("https://glottolog.org/resource/languoid/id/tupi1275","Tupian") -> Tupian
A20: utoa1244 | B20: =HYPERLINK("https://glottolog.org/resource/languoid/id/utoa1244","Uto-Aztecan") -> Uto-Aztecan
A21: unat1236 | B21: =HYPERLINK("https://glottolog.org/resource/languoid/id/unat1236","Unattested") -> Unattested
A22: cent2225 | B22: =HYPERLINK("https://glottolog.org/resource/languoid/id/cent2225","Central Sudanic") -> Central Sudanic
A23: nucl1708 | B23: =HYPERLINK("https://glottolog.org/resource/languoid/id/nucl1708","Nuclear Torricelli") -> Nuclear Torricelli
A24: nilo1247 | B24: =HYPERLINK("https://glottolog.org/resource/languoid/id/nilo1247","Nilotic") -> Nilotic
A25: ural1272 | B25: =HYPERLINK("https://glottolog.org/resource/languoid/id/ural1272","Uralic") -> Uralic
A26: algi1248 | B26: =HYPERLINK("https://glottolog.org/resource/languoid/id/algi1248","Algic") -> Algic
A27: atha1245 | B27: =HYPERLINK("https://glottolog.org/resource/languoid/id/atha1245","Athabaskan-Eyak-Tlingit") -> Athabaskan-Eyak-Tlingit
A28: pano1259 | B28: =HYPERLINK("https://glottolog.org/resource/languoid/id/pano1259","Pano-Tacanan") -> Pano-Tacanan
A29: quec1387 | B29: =HYPERLINK("https://glottolog.org/resource/languoid/id/quec1387","Quechuan") -> Quechuan
A30: turk1311 | B30: =HYPERLINK("https://glottolog.org/resource/languoid/id/turk1311","Turkic") -> Turkic
A31: cari1283 | B31: =HYPERLINK("https://glottolog.org/resource/languoid/id/cari1283","Cariban") -> Cariban
A32: hmon1336 | B32: =HYPERLINK("https://glottolog.org/resource/languoid/id/hmon1336","Hmong-Mien") -> Hmong-Mien
A33: sepi1257 | B33: =HYPERLINK("https://glottolog.org/resource/languoid/id/sepi1257","Sepik") -> Sepik
A34: nakh1245 | B34: =HYPERLINK("https://glottolog.org/resource/languoid/id/nakh1245","Nakh-Daghestanian") -> Nakh-Daghestanian
A35: maya1287 | B35: =HYPERLINK("https://glottolog.org/resource/languoid/id/maya1287","Mayan") -> Mayan
A36: lowe1437 | B36: =HYPERLINK("https://glottolog.org/resource/languoid/id/lowe1437","Lower Sepik-Ramu") -> Lower Sepik-Ramu
A37: nucl1710 | B37: =HYPERLINK("https://glottolog.org/resource/languoid/id/nucl1710","Nuclear-Macro-Je") -> Nuclear-Macro-Je
A38: chib1249 | B38: =HYPERLINK("https://glottolog.org/resource/languoid/id/chib1249","Chibchan") -> Chibchan
A39: tuca1253 | B39: =HYPERLINK("https://glottolog.org/resource/languoid/id/tuca1253","Tucanoan") -> Tucanoan
A40: sali1255 | B40: =HYPERLINK("https://glottolog.org/resource/languoid/id/sali1255","Salishan") -> Salishan
...
